<robot name="c_spray_robot">

    <link name="base_link">
       <inertial>
         <origin xyz="0 0 0" rpy="0 0 0"/>
         <mass value="1000000"/>
         <inertia ixx="100"  ixy="0"  ixz="0" iyy="100" iyz="0" izz="100" />
       </inertial>
    
       <visual>
       <origin xyz="0 0 0" rpy="0 0 0" />
        <geometry>
          <box size="2 1.8 0.76" />
        </geometry>
        <material name="white">
          <color rgba="0 1.0 1.0 1.0"/>
        </material>
      </visual>
   
      <collision>
        <origin xyz="0 0 0" rpy="0 0 0"/>
        <geometry>
          <box size="2 1.8 0.76" />
        </geometry>
      </collision>
    </link>

    <joint name="base_link_to_platform" type="revolute">
        <origin xyz="0 0 0.8" rpy="0 0 0"/>
        <parent link="base_link"/>
        <child link="platform"/>
        <axis xyz="0.0 0.0 1.0"/>
        <calibration rising="0.0"/>
        <dynamics damping="0.0" friction="0.0"/>
        <limit effort="30" velocity="1.0" lower="-1.5" upper="1.5" />
        <safety_controller k_velocity="10" k_position="15" soft_lower_limit="-2.0" soft_upper_limit="0.5" />
    </joint>




    <link name="platform">
       <inertial>
         <origin xyz="0 0 0" rpy="0 0 0"/>
         <mass value="1000000"/>
         <inertia ixx="100"  ixy="0"  ixz="0" iyy="100" iyz="0" izz="100" />
       </inertial>
    
       <visual>
       <origin xyz="0 0 0" rpy="0 0 0" />
        <geometry>
          <box size="2.5 1.8 0.76" />
        </geometry>
        <material name="white">
          <color rgba="0 1.0 1.0 1.0"/>
        </material>
      </visual>
   
      <collision>
        <origin xyz="0 0 0" rpy="0 0 0"/>
        <geometry>
          <box size="2.5 1.8 0.76" />
        </geometry>
      </collision>
    </link>

    <joint name="platform_to_arm_1" type="revolute">
        <origin xyz="1.25 0 0.5" rpy="0 0 0"/>
        <parent link="platform"/>
        <child link="arm_1"/>
        <axis xyz="0.0 1.0 0.0"/>
        <calibration rising="0.0"/>
        <dynamics damping="0.0" friction="0.0"/>
        <limit effort="30" velocity="1.0" lower="0" upper="1" />
        <safety_controller k_velocity="10" k_position="15" soft_lower_limit="-2.0" soft_upper_limit="0.5" />
    </joint>
    
    <link name="arm_1">
       <inertial>
         <origin xyz="-1.25 0 0" rpy="0 0 0"/>
         <mass value="100"/>
         <inertia ixx="100"  ixy="0"  ixz="0" iyy="100" iyz="0" izz="100" />
       </inertial>
    
       <visual>
       <origin xyz="-1.25 0 0" rpy="0 0 0" />
        <geometry>
          <box size="2.5 0.2 0.2" />
        </geometry>
        <material name="white">
          <color rgba="0 1.0 1.0 1.0"/>
        </material>
      </visual>
   
      <collision>
        <origin xyz="-1.25 0 0" rpy="0 0 0"/>
        <geometry>
          <box size="2.5 0.2 0.2" />
        </geometry>
      </collision>
    </link>

    <joint name="arm_1_to_arm_2" type="revolute">
        <origin xyz="-2.5 0 0.2" rpy="0 0 0"/>
        <parent link="arm_1"/>
        <child link="arm_2"/>
        <axis xyz="0.0 1.0 0.0"/>
        <calibration rising="0.0"/>
        <dynamics damping="0.0" friction="0.0"/>
        <limit effort="30" velocity="1.0" lower="-1.5" upper="0" />
        <safety_controller k_velocity="10" k_position="15" soft_lower_limit="-2.0" soft_upper_limit="0.5" />
    </joint>
    
    <link name="arm_2">
       <inertial>
         <origin xyz="4 0 0" rpy="0 0 0"/>
         <mass value="100"/>
         <inertia ixx="100"  ixy="0"  ixz="0" iyy="100" iyz="0" izz="100" />
       </inertial>
    
       <visual>
       <origin xyz="4 0 0" rpy="0 0 0" />
        <geometry>
          <box size="8 0.2 0.2" />
        </geometry>
        <material name="white">
          <color rgba="0 1.0 1.0 1.0"/>
        </material>
      </visual>
   
      <collision>
        <origin xyz="4 0 0" rpy="0 0 0"/>
        <geometry>
          <box size="8 0.2 0.2" />
        </geometry>
      </collision>
    </link>

    <joint name="arm_2_to_arm_3" type="revolute">
        <origin xyz="8 0 -0.2" rpy="0 0 0"/>
        <parent link="arm_2"/>
        <child link="arm_3"/>
        <axis xyz="0.0 1.0 0.0"/>
        <calibration rising="0.0"/>
        <dynamics damping="0.0" friction="0.0"/>
        <limit effort="30" velocity="1.0" lower="0" upper="3.14" />
        <safety_controller k_velocity="10" k_position="15" soft_lower_limit="-2.0" soft_upper_limit="0.5" />
    </joint>
    
    <link name="arm_3">
       <inertial>
         <origin xyz="1 0 0" rpy="0 0 0"/>
         <mass value="100"/>
         <inertia ixx="100"  ixy="0"  ixz="0" iyy="100" iyz="0" izz="100" />
       </inertial>
    
       <visual>
       <origin xyz="1 0 0" rpy="0 0 0" />
        <geometry>
          <box size="2 0.2 0.2" />
        </geometry>
        <material name="black">
          <color rgba="0 1.0 1.0 1.0"/>
        </material>
      </visual>
   
      <collision>
        <origin xyz="1 0 0" rpy="0 0 0"/>
        <geometry>
          <box size="2 0.2 0.2" />
        </geometry>
      </collision>
    </link>





</robot>